<?xml version="1.0" encoding="UTF-8"?>
<!--
  Mars Hexacopter Base Model + 2x Mini CMG 500 (Momentum Space)
  5.0 kg total, 6 rotors × 2-blade, R=0.44m
  CMG: 2x CSCMG (gimbal axis Y, spin axis X)

  Mini CMG 500 specs:
    Mass per unit:     0.44 kg
    Wheel MOI (spin):  1.603e-4 kg·m²
    Max wheel speed:   30000 RPM (3141.6 rad/s)
    Max angular mom.:  0.5 Nms
    Max torque:        1.0 Nm
    Gimbal rate:       2.0 rad/s
    Dimensions:        80×80×105 mm

  Reference:
    Yang et al., "Disturbance Robust Attitude Stabilization of
    Multirotors with Control Moment Gyros," Sensors 2024, 24, 8212

  Rotor layout (top view, CCW positive yaw):
        2(CCW)   1(CW)
          \       /
    3(CW) -- HUB -- 0(CCW)
          /       \
        4(CCW)   5(CW)

  CMG layout (inside hub):
    CMG1: +X side (pos=[+0.06, 0, 0])
    CMG2: -X side (pos=[-0.06, 0, 0])
    Gimbal axis: Y, Spin axis: X
-->
<sdf version='1.9'>
  <model name='mars_hexacopter_cmg500_base'>
    <pose>0 0 0.22 0 0 0</pose>
    <self_collide>false</self_collide>
    <static>false</static>

    <!-- ============================================ -->
    <!-- base_link: hub + arms + motors + landing gear -->
    <!-- Mass: 5.0 - 6×0.055(rotor) - 2×0.44(CMG) = 3.790 -->
    <!-- ============================================ -->
    <link name="base_link">
      <inertial>
        <mass>3.790</mass>
        <inertia>
          <ixx>0.34310</ixx>
          <ixy>0</ixy>
          <ixz>0</ixz>
          <iyy>0.34310</iyy>
          <iyz>0</iyz>
          <izz>0.68200</izz>
        </inertia>
      </inertial>
      <gravity>true</gravity>
      <velocity_decay/>

      <!-- Central hub (cylinder r=0.15, h=0.10) -->
      <visual name="hub_visual">
        <pose>0 0 0 0 0 0</pose>
        <geometry>
          <cylinder>
            <radius>0.15</radius>
            <length>0.10</length>
          </cylinder>
        </geometry>
        <material>
          <ambient>0.2 0.2 0.2 1</ambient>
          <diffuse>0.3 0.3 0.3 1</diffuse>
        </material>
      </visual>

      <!-- Arm 0: 0° -->
      <visual name="arm_0_visual">
        <pose>0.55 0 0 0 0 0</pose>
        <geometry>
          <box><size>0.80 0.03 0.02</size></box>
        </geometry>
        <material>
          <ambient>0.15 0.15 0.15 1</ambient>
          <diffuse>0.25 0.25 0.25 1</diffuse>
        </material>
      </visual>

      <!-- Arm 1: 60° -->
      <visual name="arm_1_visual">
        <pose>0.275 0.47631 0 0 0 1.0472</pose>
        <geometry>
          <box><size>0.80 0.03 0.02</size></box>
        </geometry>
        <material>
          <ambient>0.15 0.15 0.15 1</ambient>
          <diffuse>0.25 0.25 0.25 1</diffuse>
        </material>
      </visual>

      <!-- Arm 2: 120° -->
      <visual name="arm_2_visual">
        <pose>-0.275 0.47631 0 0 0 2.0944</pose>
        <geometry>
          <box><size>0.80 0.03 0.02</size></box>
        </geometry>
        <material>
          <ambient>0.15 0.15 0.15 1</ambient>
          <diffuse>0.25 0.25 0.25 1</diffuse>
        </material>
      </visual>

      <!-- Arm 3: 180° -->
      <visual name="arm_3_visual">
        <pose>-0.55 0 0 0 0 3.1416</pose>
        <geometry>
          <box><size>0.80 0.03 0.02</size></box>
        </geometry>
        <material>
          <ambient>0.15 0.15 0.15 1</ambient>
          <diffuse>0.25 0.25 0.25 1</diffuse>
        </material>
      </visual>

      <!-- Arm 4: 240° -->
      <visual name="arm_4_visual">
        <pose>-0.275 -0.47631 0 0 0 4.1888</pose>
        <geometry>
          <box><size>0.80 0.03 0.02</size></box>
        </geometry>
        <material>
          <ambient>0.15 0.15 0.15 1</ambient>
          <diffuse>0.25 0.25 0.25 1</diffuse>
        </material>
      </visual>

      <!-- Arm 5: 300° -->
      <visual name="arm_5_visual">
        <pose>0.275 -0.47631 0 0 0 5.2360</pose>
        <geometry>
          <box><size>0.80 0.03 0.02</size></box>
        </geometry>
        <material>
          <ambient>0.15 0.15 0.15 1</ambient>
          <diffuse>0.25 0.25 0.25 1</diffuse>
        </material>
      </visual>

      <!-- Motor pods (small cylinders at arm tips) -->
      <visual name="motor_pod_0">
        <pose>0.95 0 0.02 0 0 0</pose>
        <geometry><cylinder><radius>0.03</radius><length>0.04</length></cylinder></geometry>
        <material><ambient>0.3 0.1 0.1 1</ambient><diffuse>0.5 0.15 0.15 1</diffuse></material>
      </visual>
      <visual name="motor_pod_1">
        <pose>0.475 0.82272 0.02 0 0 0</pose>
        <geometry><cylinder><radius>0.03</radius><length>0.04</length></cylinder></geometry>
        <material><ambient>0.3 0.1 0.1 1</ambient><diffuse>0.5 0.15 0.15 1</diffuse></material>
      </visual>
      <visual name="motor_pod_2">
        <pose>-0.475 0.82272 0.02 0 0 0</pose>
        <geometry><cylinder><radius>0.03</radius><length>0.04</length></cylinder></geometry>
        <material><ambient>0.3 0.1 0.1 1</ambient><diffuse>0.5 0.15 0.15 1</diffuse></material>
      </visual>
      <visual name="motor_pod_3">
        <pose>-0.95 0 0.02 0 0 0</pose>
        <geometry><cylinder><radius>0.03</radius><length>0.04</length></cylinder></geometry>
        <material><ambient>0.3 0.1 0.1 1</ambient><diffuse>0.5 0.15 0.15 1</diffuse></material>
      </visual>
      <visual name="motor_pod_4">
        <pose>-0.475 -0.82272 0.02 0 0 0</pose>
        <geometry><cylinder><radius>0.03</radius><length>0.04</length></cylinder></geometry>
        <material><ambient>0.3 0.1 0.1 1</ambient><diffuse>0.5 0.15 0.15 1</diffuse></material>
      </visual>
      <visual name="motor_pod_5">
        <pose>0.475 -0.82272 0.02 0 0 0</pose>
        <geometry><cylinder><radius>0.03</radius><length>0.04</length></cylinder></geometry>
        <material><ambient>0.3 0.1 0.1 1</ambient><diffuse>0.5 0.15 0.15 1</diffuse></material>
      </visual>

      <!-- Landing gear: 3 legs at 0°, 120°, 240° -->
      <visual name="leg_0_visual">
        <pose>0.15 0 -0.135 0 0 0</pose>
        <geometry><box><size>0.015 0.015 0.17</size></box></geometry>
        <material><ambient>0.2 0.2 0.2 1</ambient><diffuse>0.3 0.3 0.3 1</diffuse></material>
      </visual>
      <visual name="leg_1_visual">
        <pose>-0.075 0.130 -0.135 0 0 0</pose>
        <geometry><box><size>0.015 0.015 0.17</size></box></geometry>
        <material><ambient>0.2 0.2 0.2 1</ambient><diffuse>0.3 0.3 0.3 1</diffuse></material>
      </visual>
      <visual name="leg_2_visual">
        <pose>-0.075 -0.130 -0.135 0 0 0</pose>
        <geometry><box><size>0.015 0.015 0.17</size></box></geometry>
        <material><ambient>0.2 0.2 0.2 1</ambient><diffuse>0.3 0.3 0.3 1</diffuse></material>
      </visual>
      <visual name="foot_0">
        <pose>0.15 0 -0.22 0 0 1.5708</pose>
        <geometry><box><size>0.30 0.015 0.015</size></box></geometry>
        <material><ambient>0.2 0.2 0.2 1</ambient><diffuse>0.3 0.3 0.3 1</diffuse></material>
      </visual>
      <visual name="foot_1">
        <pose>-0.075 0.130 -0.22 0 0 0.5236</pose>
        <geometry><box><size>0.30 0.015 0.015</size></box></geometry>
        <material><ambient>0.2 0.2 0.2 1</ambient><diffuse>0.3 0.3 0.3 1</diffuse></material>
      </visual>
      <visual name="foot_2">
        <pose>-0.075 -0.130 -0.22 0 0 -0.5236</pose>
        <geometry><box><size>0.30 0.015 0.015</size></box></geometry>
        <material><ambient>0.2 0.2 0.2 1</ambient><diffuse>0.3 0.3 0.3 1</diffuse></material>
      </visual>

      <!-- Collision: central hub -->
      <collision name="hub_collision">
        <pose>0 0 0 0 0 0</pose>
        <geometry>
          <cylinder>
            <radius>0.15</radius>
            <length>0.10</length>
          </cylinder>
        </geometry>
        <surface>
          <contact><ode><min_depth>0.001</min_depth><max_vel>0</max_vel></ode></contact>
          <friction><ode/></friction>
        </surface>
      </collision>
      <!-- Collision: landing gear feet -->
      <collision name="foot_0_collision">
        <pose>0.15 0 -0.20 0 0 1.5708</pose>
        <geometry><box><size>0.30 0.04 0.06</size></box></geometry>
        <surface>
          <contact><ode><min_depth>0.002</min_depth><max_vel>0</max_vel></ode></contact>
          <friction><ode><mu>1.0</mu><mu2>1.0</mu2></ode></friction>
        </surface>
      </collision>
      <collision name="foot_1_collision">
        <pose>-0.075 0.130 -0.20 0 0 0.5236</pose>
        <geometry><box><size>0.30 0.04 0.06</size></box></geometry>
        <surface>
          <contact><ode><min_depth>0.002</min_depth><max_vel>0</max_vel></ode></contact>
          <friction><ode><mu>1.0</mu><mu2>1.0</mu2></ode></friction>
        </surface>
      </collision>
      <collision name="foot_2_collision">
        <pose>-0.075 -0.130 -0.20 0 0 -0.5236</pose>
        <geometry><box><size>0.30 0.04 0.06</size></box></geometry>
        <surface>
          <contact><ode><min_depth>0.002</min_depth><max_vel>0</max_vel></ode></contact>
          <friction><ode><mu>1.0</mu><mu2>1.0</mu2></ode></friction>
        </surface>
      </collision>

      <!-- Sensors -->
      <sensor name="imu_sensor" type="imu">
        <gz_frame_id>base_link</gz_frame_id>
        <always_on>1</always_on>
        <update_rate>250</update_rate>
        <imu>
          <angular_velocity>
            <x><noise type="gaussian"><mean>0.0</mean><stddev>0.0008726646</stddev></noise></x>
            <y><noise type="gaussian"><mean>0.0</mean><stddev>0.0008726646</stddev></noise></y>
            <z><noise type="gaussian"><mean>0.0</mean><stddev>0.0008726646</stddev></noise></z>
          </angular_velocity>
          <linear_acceleration>
            <x><noise type="gaussian"><mean>0.0</mean><stddev>0.00637</stddev></noise></x>
            <y><noise type="gaussian"><mean>0.0</mean><stddev>0.00637</stddev></noise></y>
            <z><noise type="gaussian"><mean>0.0</mean><stddev>0.00686</stddev></noise></z>
          </linear_acceleration>
        </imu>
      </sensor>
      <sensor name="air_pressure_sensor" type="air_pressure">
        <gz_frame_id>base_link</gz_frame_id>
        <always_on>1</always_on>
        <update_rate>50</update_rate>
        <air_pressure>
          <pressure><noise type="gaussian"><mean>0</mean><stddev>3</stddev></noise></pressure>
        </air_pressure>
      </sensor>
      <sensor name="navsat_sensor" type="navsat">
        <gz_frame_id>base_link</gz_frame_id>
        <always_on>1</always_on>
        <update_rate>30</update_rate>
      </sensor>

      <!-- ===== Body-frame coordinate axes (RGB = XYZ, no collision) ===== -->
      <!-- All axes at z=0.06 (above hub top surface) to avoid arm overlap -->
      <!-- X axis — Red shaft -->
      <visual name="axis_x_shaft">
        <pose>0.15 0 0.06 0 1.5708 0</pose>
        <geometry><cylinder><radius>0.006</radius><length>0.30</length></cylinder></geometry>
        <material><ambient>0.9 0.0 0.0 1</ambient><diffuse>1.0 0.0 0.0 1</diffuse></material>
      </visual>
      <!-- X axis — Red arrowhead -->
      <visual name="axis_x_tip">
        <pose>0.31 0 0.06 0 0 0</pose>
        <geometry><box><size>0.025 0.02 0.02</size></box></geometry>
        <material><ambient>0.9 0.0 0.0 1</ambient><diffuse>1.0 0.0 0.0 1</diffuse></material>
      </visual>

      <!-- Y axis — Green shaft -->
      <visual name="axis_y_shaft">
        <pose>0 0.15 0.06 1.5708 0 0</pose>
        <geometry><cylinder><radius>0.006</radius><length>0.30</length></cylinder></geometry>
        <material><ambient>0.0 0.9 0.0 1</ambient><diffuse>0.0 1.0 0.0 1</diffuse></material>
      </visual>
      <!-- Y axis — Green arrowhead -->
      <visual name="axis_y_tip">
        <pose>0 0.31 0.06 0 0 0</pose>
        <geometry><box><size>0.02 0.025 0.02</size></box></geometry>
        <material><ambient>0.0 0.9 0.0 1</ambient><diffuse>0.0 1.0 0.0 1</diffuse></material>
      </visual>

      <!-- Z axis — Blue shaft -->
      <visual name="axis_z_shaft">
        <pose>0 0 0.21 0 0 0</pose>
        <geometry><cylinder><radius>0.006</radius><length>0.30</length></cylinder></geometry>
        <material><ambient>0.0 0.0 0.9 1</ambient><diffuse>0.0 0.0 1.0 1</diffuse></material>
      </visual>
      <!-- Z axis — Blue arrowhead -->
      <visual name="axis_z_tip">
        <pose>0 0 0.37 0 0 0</pose>
        <geometry><box><size>0.02 0.02 0.025</size></box></geometry>
        <material><ambient>0.0 0.0 0.9 1</ambient><diffuse>0.0 0.0 1.0 1</diffuse></material>
      </visual>
    </link>

    <!-- ============================================ -->
    <!-- Rotor 0: 0° (CCW) -->
    <!-- ============================================ -->
    <link name="rotor_0">
      <gravity>true</gravity>
      <self_collide>false</self_collide>
      <velocity_decay/>
      <pose>0.95 0 0.06 0 0 0</pose>
      <inertial>
        <mass>0.055</mass>
        <inertia>
          <ixx>1.0e-05</ixx>
          <iyy>3.549333e-03</iyy>
          <izz>3.549333e-03</izz>
        </inertia>
      </inertial>
      <visual name="rotor_0_blade">
        <geometry>
          <box><size>0.88 0.10 0.005</size></box>
        </geometry>
        <material>
          <ambient>0.3 0.3 0.3 0.9</ambient>
          <diffuse>0.45 0.45 0.45 0.9</diffuse>
        </material>
      </visual>
      <visual name="rotor_0_hub">
        <geometry>
          <cylinder><radius>0.02</radius><length>0.015</length></cylinder>
        </geometry>
        <material>
          <ambient>0.2 0.2 0.2 1</ambient>
          <diffuse>0.3 0.3 0.3 1</diffuse>
        </material>
      </visual>
    </link>
    <joint name="rotor_0_joint" type="revolute">
      <parent>base_link</parent>
      <child>rotor_0</child>
      <axis>
        <xyz>0 0 1</xyz>
        <limit><lower>-1e+16</lower><upper>1e+16</upper></limit>
        <dynamics><spring_reference>0</spring_reference><spring_stiffness>0</spring_stiffness></dynamics>
      </axis>
    </joint>

    <!-- ============================================ -->
    <!-- Rotor 1: 60° (CW) -->
    <!-- ============================================ -->
    <link name="rotor_1">
      <gravity>true</gravity>
      <self_collide>false</self_collide>
      <velocity_decay/>
      <pose>0.475 0.82272 0.06 0 0 0</pose>
      <inertial>
        <mass>0.055</mass>
        <inertia>
          <ixx>1.0e-05</ixx>
          <iyy>3.549333e-03</iyy>
          <izz>3.549333e-03</izz>
        </inertia>
      </inertial>
      <visual name="rotor_1_blade">
        <geometry>
          <box><size>0.88 0.10 0.005</size></box>
        </geometry>
        <material>
          <ambient>0.3 0.3 0.3 0.9</ambient>
          <diffuse>0.45 0.45 0.45 0.9</diffuse>
        </material>
      </visual>
      <visual name="rotor_1_hub">
        <geometry>
          <cylinder><radius>0.02</radius><length>0.015</length></cylinder>
        </geometry>
        <material>
          <ambient>0.2 0.2 0.2 1</ambient>
          <diffuse>0.3 0.3 0.3 1</diffuse>
        </material>
      </visual>
    </link>
    <joint name="rotor_1_joint" type="revolute">
      <parent>base_link</parent>
      <child>rotor_1</child>
      <axis>
        <xyz>0 0 1</xyz>
        <limit><lower>-1e+16</lower><upper>1e+16</upper></limit>
        <dynamics><spring_reference>0</spring_reference><spring_stiffness>0</spring_stiffness></dynamics>
      </axis>
    </joint>

    <!-- ============================================ -->
    <!-- Rotor 2: 120° (CCW) -->
    <!-- ============================================ -->
    <link name="rotor_2">
      <gravity>true</gravity>
      <self_collide>false</self_collide>
      <velocity_decay/>
      <pose>-0.475 0.82272 0.06 0 0 0</pose>
      <inertial>
        <mass>0.055</mass>
        <inertia>
          <ixx>1.0e-05</ixx>
          <iyy>3.549333e-03</iyy>
          <izz>3.549333e-03</izz>
        </inertia>
      </inertial>
      <visual name="rotor_2_blade">
        <geometry>
          <box><size>0.88 0.10 0.005</size></box>
        </geometry>
        <material>
          <ambient>0.3 0.3 0.3 0.9</ambient>
          <diffuse>0.45 0.45 0.45 0.9</diffuse>
        </material>
      </visual>
      <visual name="rotor_2_hub">
        <geometry>
          <cylinder><radius>0.02</radius><length>0.015</length></cylinder>
        </geometry>
        <material>
          <ambient>0.2 0.2 0.2 1</ambient>
          <diffuse>0.3 0.3 0.3 1</diffuse>
        </material>
      </visual>
    </link>
    <joint name="rotor_2_joint" type="revolute">
      <parent>base_link</parent>
      <child>rotor_2</child>
      <axis>
        <xyz>0 0 1</xyz>
        <limit><lower>-1e+16</lower><upper>1e+16</upper></limit>
        <dynamics><spring_reference>0</spring_reference><spring_stiffness>0</spring_stiffness></dynamics>
      </axis>
    </joint>

    <!-- ============================================ -->
    <!-- Rotor 3: 180° (CW) -->
    <!-- ============================================ -->
    <link name="rotor_3">
      <gravity>true</gravity>
      <self_collide>false</self_collide>
      <velocity_decay/>
      <pose>-0.95 0 0.06 0 0 0</pose>
      <inertial>
        <mass>0.055</mass>
        <inertia>
          <ixx>1.0e-05</ixx>
          <iyy>3.549333e-03</iyy>
          <izz>3.549333e-03</izz>
        </inertia>
      </inertial>
      <visual name="rotor_3_blade">
        <geometry>
          <box><size>0.88 0.10 0.005</size></box>
        </geometry>
        <material>
          <ambient>0.3 0.3 0.3 0.9</ambient>
          <diffuse>0.45 0.45 0.45 0.9</diffuse>
        </material>
      </visual>
      <visual name="rotor_3_hub">
        <geometry>
          <cylinder><radius>0.02</radius><length>0.015</length></cylinder>
        </geometry>
        <material>
          <ambient>0.2 0.2 0.2 1</ambient>
          <diffuse>0.3 0.3 0.3 1</diffuse>
        </material>
      </visual>
    </link>
    <joint name="rotor_3_joint" type="revolute">
      <parent>base_link</parent>
      <child>rotor_3</child>
      <axis>
        <xyz>0 0 1</xyz>
        <limit><lower>-1e+16</lower><upper>1e+16</upper></limit>
        <dynamics><spring_reference>0</spring_reference><spring_stiffness>0</spring_stiffness></dynamics>
      </axis>
    </joint>

    <!-- ============================================ -->
    <!-- Rotor 4: 240° (CCW) -->
    <!-- ============================================ -->
    <link name="rotor_4">
      <gravity>true</gravity>
      <self_collide>false</self_collide>
      <velocity_decay/>
      <pose>-0.475 -0.82272 0.06 0 0 0</pose>
      <inertial>
        <mass>0.055</mass>
        <inertia>
          <ixx>1.0e-05</ixx>
          <iyy>3.549333e-03</iyy>
          <izz>3.549333e-03</izz>
        </inertia>
      </inertial>
      <visual name="rotor_4_blade">
        <geometry>
          <box><size>0.88 0.10 0.005</size></box>
        </geometry>
        <material>
          <ambient>0.3 0.3 0.3 0.9</ambient>
          <diffuse>0.45 0.45 0.45 0.9</diffuse>
        </material>
      </visual>
      <visual name="rotor_4_hub">
        <geometry>
          <cylinder><radius>0.02</radius><length>0.015</length></cylinder>
        </geometry>
        <material>
          <ambient>0.2 0.2 0.2 1</ambient>
          <diffuse>0.3 0.3 0.3 1</diffuse>
        </material>
      </visual>
    </link>
    <joint name="rotor_4_joint" type="revolute">
      <parent>base_link</parent>
      <child>rotor_4</child>
      <axis>
        <xyz>0 0 1</xyz>
        <limit><lower>-1e+16</lower><upper>1e+16</upper></limit>
        <dynamics><spring_reference>0</spring_reference><spring_stiffness>0</spring_stiffness></dynamics>
      </axis>
    </joint>

    <!-- ============================================ -->
    <!-- Rotor 5: 300° (CW) -->
    <!-- ============================================ -->
    <link name="rotor_5">
      <gravity>true</gravity>
      <self_collide>false</self_collide>
      <velocity_decay/>
      <pose>0.475 -0.82272 0.06 0 0 0</pose>
      <inertial>
        <mass>0.055</mass>
        <inertia>
          <ixx>1.0e-05</ixx>
          <iyy>3.549333e-03</iyy>
          <izz>3.549333e-03</izz>
        </inertia>
      </inertial>
      <visual name="rotor_5_blade">
        <geometry>
          <box><size>0.88 0.10 0.005</size></box>
        </geometry>
        <material>
          <ambient>0.3 0.3 0.3 0.9</ambient>
          <diffuse>0.45 0.45 0.45 0.9</diffuse>
        </material>
      </visual>
      <visual name="rotor_5_hub">
        <geometry>
          <cylinder><radius>0.02</radius><length>0.015</length></cylinder>
        </geometry>
        <material>
          <ambient>0.2 0.2 0.2 1</ambient>
          <diffuse>0.3 0.3 0.3 1</diffuse>
        </material>
      </visual>
    </link>
    <joint name="rotor_5_joint" type="revolute">
      <parent>base_link</parent>
      <child>rotor_5</child>
      <axis>
        <xyz>0 0 1</xyz>
        <limit><lower>-1e+16</lower><upper>1e+16</upper></limit>
        <dynamics><spring_reference>0</spring_reference><spring_stiffness>0</spring_stiffness></dynamics>
      </axis>
    </joint>

    <!-- ============================================ -->
    <!-- CMG 1: +X side — Mini CMG 500 -->
    <!-- Gimbal axis: Y, Spin axis: X -->
    <!-- ============================================ -->
    <link name="cmg1_gimbal">
      <pose relative_to="base_link">0.06 0 -0.10 0 0 0</pose>
      <inertial>
        <mass>0.16</mass>
        <inertia>
          <ixx>5.0e-5</ixx> <iyy>5.0e-5</iyy> <izz>5.0e-5</izz>
          <ixy>0</ixy> <ixz>0</ixz> <iyz>0</iyz>
        </inertia>
      </inertial>
      <!-- Gimbal shaft (Y-axis, visible frame) -->
      <visual name="cmg1_gimbal_shaft">
        <pose>0 0 0 1.5708 0 0</pose>
        <geometry><cylinder><radius>0.012</radius><length>0.10</length></cylinder></geometry>
        <material>
          <ambient>0.0 0.0 0.8 1</ambient>
          <diffuse>0.1 0.1 1.0 1</diffuse>
        </material>
      </visual>
      <!-- Gimbal mounting brackets (±Y ends) -->
      <visual name="cmg1_bracket_top">
        <pose>0 0.045 0 0 0 0</pose>
        <geometry><box><size>0.04 0.01 0.04</size></box></geometry>
        <material><ambient>0.3 0.3 0.3 1</ambient><diffuse>0.4 0.4 0.4 1</diffuse></material>
      </visual>
      <visual name="cmg1_bracket_bot">
        <pose>0 -0.045 0 0 0 0</pose>
        <geometry><box><size>0.04 0.01 0.04</size></box></geometry>
        <material><ambient>0.3 0.3 0.3 1</ambient><diffuse>0.4 0.4 0.4 1</diffuse></material>
      </visual>
    </link>

    <link name="cmg1_wheel">
      <pose relative_to="cmg1_gimbal">0 0 0 0 0 0</pose>
      <inertial>
        <mass>0.28</mass>
        <inertia>
          <ixx>1.603e-4</ixx> <iyy>9.0e-5</iyy> <izz>9.0e-5</izz>
          <ixy>0</ixy> <ixz>0</ixz> <iyz>0</iyz>
        </inertia>
      </inertial>
      <!-- Flywheel disk (R=35mm, L=30mm) -->
      <visual name="cmg1_wheel_visual">
        <pose>0 0 0 0 1.5708 0</pose>
        <geometry><cylinder><radius>0.035</radius><length>0.03</length></cylinder></geometry>
        <material>
          <ambient>0.9 0.2 0.2 1</ambient>
          <diffuse>1.0 0.3 0.3 1</diffuse>
        </material>
      </visual>
      <!-- Cross stripes for rotation visualization (protrude beyond wheel disk) -->
      <visual name="cmg1_stripe_y">
        <geometry><box><size>0.04 0.065 0.008</size></box></geometry>
        <material><ambient>1.0 1.0 0.0 1</ambient><diffuse>1.0 1.0 0.1 1</diffuse></material>
      </visual>
      <visual name="cmg1_stripe_z">
        <geometry><box><size>0.04 0.008 0.065</size></box></geometry>
        <material><ambient>1.0 1.0 1.0 1</ambient><diffuse>1.0 1.0 1.0 1</diffuse></material>
      </visual>
    </link>

    <!-- ============================================ -->
    <!-- CMG 2: -X side — Mini CMG 500 -->
    <!-- ============================================ -->
    <link name="cmg2_gimbal">
      <pose relative_to="base_link">-0.06 0 -0.10 0 0 0</pose>
      <inertial>
        <mass>0.16</mass>
        <inertia>
          <ixx>5.0e-5</ixx> <iyy>5.0e-5</iyy> <izz>5.0e-5</izz>
          <ixy>0</ixy> <ixz>0</ixz> <iyz>0</iyz>
        </inertia>
      </inertial>
      <!-- Gimbal shaft (Y-axis, visible frame) -->
      <visual name="cmg2_gimbal_shaft">
        <pose>0 0 0 1.5708 0 0</pose>
        <geometry><cylinder><radius>0.012</radius><length>0.10</length></cylinder></geometry>
        <material>
          <ambient>0.0 0.6 0.0 1</ambient>
          <diffuse>0.1 0.8 0.1 1</diffuse>
        </material>
      </visual>
      <!-- Gimbal mounting brackets (±Y ends) -->
      <visual name="cmg2_bracket_top">
        <pose>0 0.045 0 0 0 0</pose>
        <geometry><box><size>0.04 0.01 0.04</size></box></geometry>
        <material><ambient>0.3 0.3 0.3 1</ambient><diffuse>0.4 0.4 0.4 1</diffuse></material>
      </visual>
      <visual name="cmg2_bracket_bot">
        <pose>0 -0.045 0 0 0 0</pose>
        <geometry><box><size>0.04 0.01 0.04</size></box></geometry>
        <material><ambient>0.3 0.3 0.3 1</ambient><diffuse>0.4 0.4 0.4 1</diffuse></material>
      </visual>
    </link>

    <link name="cmg2_wheel">
      <pose relative_to="cmg2_gimbal">0 0 0 0 0 0</pose>
      <inertial>
        <mass>0.28</mass>
        <inertia>
          <ixx>1.603e-4</ixx> <iyy>9.0e-5</iyy> <izz>9.0e-5</izz>
          <ixy>0</ixy> <ixz>0</ixz> <iyz>0</iyz>
        </inertia>
      </inertial>
      <!-- Flywheel disk -->
      <visual name="cmg2_wheel_visual">
        <pose>0 0 0 0 1.5708 0</pose>
        <geometry><cylinder><radius>0.035</radius><length>0.03</length></cylinder></geometry>
        <material>
          <ambient>0.9 0.2 0.2 1</ambient>
          <diffuse>1.0 0.3 0.3 1</diffuse>
        </material>
      </visual>
      <!-- Cross stripes for rotation visualization (protrude beyond wheel disk) -->
      <visual name="cmg2_stripe_y">
        <geometry><box><size>0.04 0.065 0.008</size></box></geometry>
        <material><ambient>1.0 1.0 0.0 1</ambient><diffuse>1.0 1.0 0.1 1</diffuse></material>
      </visual>
      <visual name="cmg2_stripe_z">
        <geometry><box><size>0.04 0.008 0.065</size></box></geometry>
        <material><ambient>1.0 1.0 1.0 1</ambient><diffuse>1.0 1.0 1.0 1</diffuse></material>
      </visual>
    </link>

    <!-- ============================================ -->
    <!-- CMG Joints — Mini CMG 500 limits -->
    <!-- ============================================ -->
    <joint name="cmg1_gimbal_joint" type="revolute">
      <parent>base_link</parent>
      <child>cmg1_gimbal</child>
      <axis>
        <xyz>0 1 0</xyz>
        <limit>
          <lower>-1e16</lower> <upper>1e16</upper>
          <effort>10</effort> <velocity>2.0</velocity>
        </limit>
        <dynamics><damping>0.0</damping><friction>0.0</friction></dynamics>
      </axis>
    </joint>

    <joint name="cmg1_wheel_joint" type="revolute">
      <parent>cmg1_gimbal</parent>
      <child>cmg1_wheel</child>
      <axis>
        <xyz>1 0 0</xyz>
        <limit>
          <lower>-1e16</lower> <upper>1e16</upper>
          <effort>1</effort> <velocity>3200</velocity>
        </limit>
        <dynamics><damping>0.0</damping><friction>0.0</friction></dynamics>
      </axis>
    </joint>

    <joint name="cmg2_gimbal_joint" type="revolute">
      <parent>base_link</parent>
      <child>cmg2_gimbal</child>
      <axis>
        <xyz>0 1 0</xyz>
        <limit>
          <lower>-1e16</lower> <upper>1e16</upper>
          <effort>10</effort> <velocity>2.0</velocity>
        </limit>
        <dynamics><damping>0.0</damping><friction>0.0</friction></dynamics>
      </axis>
    </joint>

    <joint name="cmg2_wheel_joint" type="revolute">
      <parent>cmg2_gimbal</parent>
      <child>cmg2_wheel</child>
      <axis>
        <xyz>1 0 0</xyz>
        <limit>
          <lower>-1e16</lower> <upper>1e16</upper>
          <effort>1</effort> <velocity>3200</velocity>
        </limit>
        <dynamics><damping>0.0</damping><friction>0.0</friction></dynamics>
      </axis>
    </joint>

  </model>
</sdf>
